Workbook
Name bauemissionen_real: 'Mapping RealwerteSpielwerte'!$B$6
Name COP_0: 'Mapping RealwerteSpielwerte'!$D$29
Name COP_1: 'Mapping RealwerteSpielwerte'!$D$30
Name COP_2: 'Mapping RealwerteSpielwerte'!$D$31
Name COP_3: 'Mapping RealwerteSpielwerte'!$D$32
Name COP_4: 'Mapping RealwerteSpielwerte'!$D$33
Name COP_5: 'Mapping RealwerteSpielwerte'!$D$34
Name heizkosten_baseline: 'Mapping RealwerteSpielwerte'!$C$28
Name kgemission_per_sp: 'Mapping RealwerteSpielwerte'!$D$4
Name kosten_bio: 'Mapping RealwerteSpielwerte'!$D$24
Name kosten_fw: 'Mapping RealwerteSpielwerte'!$D$25
Name kosten_gas: 'Mapping RealwerteSpielwerte'!$D$23
Name kosten_gruengas: 'Mapping RealwerteSpielwerte'!$D$26
Name kosten_netzstrom: 'Mapping RealwerteSpielwerte'!$D$27
Name real_zu_spiel_emissionsintensität_1: 'Mapping RealwerteSpielwerte'!$D$13
Name real_zu_spiel_emissionsintensität_2: 'Mapping RealwerteSpielwerte'!$D$14
Name real_zu_spiel_emissionsintensität_3: 'Mapping RealwerteSpielwerte'!$D$15
Name real_zu_spiel_emissionsintensität_4: 'Mapping RealwerteSpielwerte'!$D$16
Name real_zu_spiel_emissionsintensität_5: 'Mapping RealwerteSpielwerte'!$D$17
Name real_zu_spiel_netzbezug: 'Mapping RealwerteSpielwerte'!$D$10
Name real_zu_spiel_strombedarf: 'Mapping RealwerteSpielwerte'!$D$7
Name real_zu_spiel_stromproduktion: 'Mapping RealwerteSpielwerte'!$D$8
Name real_zu_spiel_stromspeicher: 'Mapping RealwerteSpielwerte'!$D$9
Name years_per_round: 'Mapping RealwerteSpielwerte'!$B$2

Sheet Massnahmenkarten Spielwerte
A1: Name | B1: Slot/Stapel | C1: Count | D1: Heizsystem | E1: Kosten | F1: BauEmissionen | G1: SofortCO2 | H1: Strombedarf | I1: Stromproduktion | J1: Stromspeicher | K1: Wärmeschutz | L1: Wärmepumpen-Effizienz | M1: Zufriedenheit | N1: SofortBudget | O1: REAL Kosten | P1: REAL BauEmissionen | Q1: REAL Sofort CO2 | R1: REAL Strombedarf | S1: REAL Stromproduktion | T1: REAL Stromspeicher | U1: REAL Wärmeschutz | V1: REAL Wärmepumpen-Effizienz | W1: Voraussetzung Spalte | X1: Voraussetzung Wert | Y1: Voraussetzung Wert NICHT | Z1: EffektParsed | AA1: Beschreibung
A2: Balkonkraftwerk | B2: *Effizienz | C2: 1 | E2: 0 | G2: =Table1[[#This Row],[REAL Sofort CO2]]/kgemission_per_sp -> 0 | H2: =Table1[[#This Row],[REAL Strombedarf]]/real_zu_spiel_strombedarf -> 0 | I2: =Table1[[#This Row],[REAL Stromproduktion]]/real_zu_spiel_stromproduktion -> 1 | J2: =Table1[[#This Row],[REAL Stromspeicher]]/real_zu_spiel_stromspeicher -> 0 | S2: 5 | Z2: =_xlfn.TEXTJOIN( "XX", TRUE, IF(OR(F2="",F2=0),"",REPT(IF(F2>0,"EN","EM"),ABS(F2))), IF(OR(H2="",H2=0),"",REPT(IF(H2>0,"BM","BP"),ABS(H2))), REPT("SP",I2), REPT("FL",J2), REPT("WS",K2), REPT("EF",L2), IF(OR(M2="",M2=0),"",REPT(IF(M2>0,"ZU","ZM"),ABS(M2))), IF(D2="FW","XXFW",IF(D2="BIO","XXBI",IF(D2="ABWWP","XXWP",IF(D2="WP","XXWP",IF(D2="GG","XXGG",""))))) ) -> SP | AA2: =CHAR(34)&VLOOKUP(Table1[[#This Row],[Name]],'Massnahmenkarten Texte'!A:C,3,FALSE)&CHAR(34) -> "Ein Balkonkraftwerk hat nur maximal 800 Watt (etwa zwei Paneele), bietet aber den Vorteil einer einfacheren Installation und Bedienung."
A3: E-Herd | B3: *Effizienz | C3: 1 | E3: 1 | F3: -4 | G3: =Table1[[#This Row],[REAL Sofort CO2]]/kgemission_per_sp -> 0 | H3: =Table1[[#This Row],[REAL Strombedarf]]/real_zu_spiel_strombedarf -> 1 | I3: =Table1[[#This Row],[REAL Stromproduktion]]/real_zu_spiel_stromproduktion -> 0 | J3: =Table1[[#This Row],[REAL Stromspeicher]]/real_zu_spiel_stromspeicher -> 0 | P3: -5 | R3: 5 | Z3: =_xlfn.TEXTJOIN( "XX", TRUE, IF(OR(F3="",F3=0),"",REPT(IF(F3>0,"EN","EM"),ABS(F3))), IF(OR(H3="",H3=0),"",REPT(IF(H3>0,"BM","BP"),ABS(H3))), REPT("SP",I3), REPT("FL",J3), REPT("WS",K3), REPT("EF",L3), IF(OR(M3="",M3=0),"",REPT(IF(M3>0,"ZU","ZM"),ABS(M3))), IF(D3="FW","XXFW",IF(D3="BIO","XXBI",IF(D3="ABWWP","XXWP",IF(D3="WP","XXWP",IF(D3="GG","XXGG",""))))) ) -> EMEMEMEMXXBM | AA3: =CHAR(34)&VLOOKUP(Table1[[#This Row],[Name]],'Massnahmenkarten Texte'!A:C,3,FALSE)&CHAR(34) -> "Ein E-Herd ersetzt das Kochen mit Gas und reduziert damit die direkte Nutzung fossiler Energie in der Wohnung. Er erhöht den Strombedarf etwas, ist aber einfach umsetzbar und verbessert die Alltagstauglichkeit eines vollständig elektrifizierten Gebäudes."
A4: Fassadenintegrierte PV | B4: *Effizienz | C4: 1 | E4: 3 | G4: =Table1[[#This Row],[REAL Sofort CO2]]/kgemission_per_sp -> 0 | H4: =Table1[[#This Row],[REAL Strombedarf]]/real_zu_spiel_strombedarf -> 0 | I4: =Table1[[#This Row],[REAL Stromproduktion]]/real_zu_spiel_stromproduktion -> 4 | J4: =Table1[[#This Row],[REAL Stromspeicher]]/real_zu_spiel_stromspeicher -> 0 | S4: 20 | W4: Name | Y4: Fassadenbegrünung | Z4: =_xlfn.TEXTJOIN( "XX", TRUE, IF(OR(F4="",F4=0),"",REPT(IF(F4>0,"EN","EM"),ABS(F4))), IF(OR(H4="",H4=0),"",REPT(IF(H4>0,"BM","BP"),ABS(H4))), REPT("SP",I4), REPT("FL",J4), REPT("WS",K4), REPT("EF",L4), IF(OR(M4="",M4=0),"",REPT(IF(M4>0,"ZU","ZM"),ABS(M4))), IF(D4="FW","XXFW",IF(D4="BIO","XXBI",IF(D4="ABWWP","XXWP",IF(D4="WP","XXWP",IF(D4="GG","XXGG",""))))) ) -> SPSPSPSP | AA4: =CHAR(34)&VLOOKUP(Table1[[#This Row],[Name]],'Massnahmenkarten Texte'!A:C,3,FALSE)&CHAR(34) -> "Fassaden-PV nutzt zusätzlich zur Dachfläche auch die Gebäudehülle zur Stromerzeugung. Sie ist teurer und stärker von Orientierung, Verschattung und Gestaltung abhängig, kann aber zusätzliche Emissionen einsparen, wenn das Dachpotenzial begrenzt ist."
A5: LED Beleuchtung | B5: *Effizienz | C5: 1 | E5: 1 | G5: =Table1[[#This Row],[REAL Sofort CO2]]/kgemission_per_sp -> 0 | H5: =Table1[[#This Row],[REAL Strombedarf]]/real_zu_spiel_strombedarf -> -1 | I5: =Table1[[#This Row],[REAL Stromproduktion]]/real_zu_spiel_stromproduktion -> 0 | J5: =Table1[[#This Row],[REAL Stromspeicher]]/real_zu_spiel_stromspeicher -> 0 | R5: -5 | Z5: =_xlfn.TEXTJOIN( "XX", TRUE, IF(OR(F5="",F5=0),"",REPT(IF(F5>0,"EN","EM"),ABS(F5))), IF(OR(H5="",H5=0),"",REPT(IF(H5>0,"BM","BP"),ABS(H5))), REPT("SP",I5), REPT("FL",J5), REPT("WS",K5), REPT("EF",L5), IF(OR(M5="",M5=0),"",REPT(IF(M5>0,"ZU","ZM"),ABS(M5))), IF(D5="FW","XXFW",IF(D5="BIO","XXBI",IF(D5="ABWWP","XXWP",IF(D5="WP","XXWP",IF(D5="GG","XXGG",""))))) ) -> BP | AA5: =CHAR(34)&VLOOKUP(Table1[[#This Row],[Name]],'Massnahmenkarten Texte'!A:C,3,FALSE)&CHAR(34) -> "LED-Beleuchtung ersetzt alte Leuchtmittel und senkt den Strombedarf für Beleuchtung deutlich. Sie ist günstig, einfach umzusetzen und verbessert je nach Bestand auch Lichtqualität und Nutzerzufriedenheit."
A6: Wärmerückgewinnung des Duschwassers | B6: *Effizienz | C6: 1 | E6: 1 | G6: =Table1[[#This Row],[REAL Sofort CO2]]/kgemission_per_sp -> 0 | H6: =Table1[[#This Row],[REAL Strombedarf]]/real_zu_spiel_strombedarf -> 0 | I6: =Table1[[#This Row],[REAL Stromproduktion]]/real_zu_spiel_stromproduktion -> 0 | J6: =Table1[[#This Row],[REAL Stromspeicher]]/real_zu_spiel_stromspeicher -> 0 | L6: 1 | R6: 0 | V6: 1 | W6: Heizsystem | X6: WP | Z6: =_xlfn.TEXTJOIN( "XX", TRUE, IF(OR(F6="",F6=0),"",REPT(IF(F6>0,"EN","EM"),ABS(F6))), IF(OR(H6="",H6=0),"",REPT(IF(H6>0,"BM","BP"),ABS(H6))), REPT("SP",I6), REPT("FL",J6), REPT("WS",K6), REPT("EF",L6), IF(OR(M6="",M6=0),"",REPT(IF(M6>0,"ZU","ZM"),ABS(M6))), IF(D6="FW","XXFW",IF(D6="BIO","XXBI",IF(D6="ABWWP","XXWP",IF(D6="WP","XXWP",IF(D6="GG","XXGG",""))))) ) -> EF | AA6: =CHAR(34)&VLOOKUP(Table1[[#This Row],[Name]],'Massnahmenkarten Texte'!A:C,3,FALSE)&CHAR(34) -> "Die Wärme des abfließenden Duschwassers wird genutzt, um frisches Wasser vorzuwärmen. Dadurch müssen Wärmepumpen weniger leisten und arbeitet effizienter, der Einbau ist aber technisch nur bei passenden Leitungswegen sinnvoll."
A7: Bi-Direktionelles Laden | B7: *Flexibilität | C7: 1 | E7: 0 | G7: =Table1[[#This Row],[REAL Sofort CO2]]/kgemission_per_sp -> 0 | H7: =Table1[[#This Row],[REAL Strombedarf]]/real_zu_spiel_strombedarf -> -2 | I7: =Table1[[#This Row],[REAL Stromproduktion]]/real_zu_spiel_stromproduktion -> 0 | J7: =Table1[[#This Row],[REAL Stromspeicher]]/real_zu_spiel_stromspeicher -> 4 | M7: -1 | R7: -10 | T7: 20 | W7: Name | X7: E-Car Lade-Infrastruktur | Z7: =_xlfn.TEXTJOIN( "XX", TRUE, IF(OR(F7="",F7=0),"",REPT(IF(F7>0,"EN","EM"),ABS(F7))), IF(OR(H7="",H7=0),"",REPT(IF(H7>0,"BM","BP"),ABS(H7))), REPT("SP",I7), REPT("FL",J7), REPT("WS",K7), REPT("EF",L7), IF(OR(M7="",M7=0),"",REPT(IF(M7>0,"ZU","ZM"),ABS(M7))), IF(D7="FW","XXFW",IF(D7="BIO","XXBI",IF(D7="ABWWP","XXWP",IF(D7="WP","XXWP",IF(D7="GG","XXGG",""))))) ) -> BPBPXXFLFLFLFLXXZM | AA7: =CHAR(34)&VLOOKUP(Table1[[#This Row],[Name]],'Massnahmenkarten Texte'!A:C,3,FALSE)&CHAR(34) -> "Ermöglicht die Lastverschiebung über den elektrischen Speicher der E-Auto-Batterie, der Abends wieder teilweise entladen wird. Die Unterstützung der Nutzer ist allerdings nötig."
A8: Effiziente Haushaltsgeräte | B8: *Flexibilität | C8: 1 | E8: 1 | G8: =Table1[[#This Row],[REAL Sofort CO2]]/kgemission_per_sp -> 0 | H8: =Table1[[#This Row],[REAL Strombedarf]]/real_zu_spiel_strombedarf -> -1 | I8: =Table1[[#This Row],[REAL Stromproduktion]]/real_zu_spiel_stromproduktion -> 0 | J8: =Table1[[#This Row],[REAL Stromspeicher]]/real_zu_spiel_stromspeicher -> 0 | R8: -5 | W8: Heizsystem | X8: WP | Z8: =_xlfn.TEXTJOIN( "XX", TRUE, IF(OR(F8="",F8=0),"",REPT(IF(F8>0,"EN","EM"),ABS(F8))), IF(OR(H8="",H8=0),"",REPT(IF(H8>0,"BM","BP"),ABS(H8))), REPT("SP",I8), REPT("FL",J8), REPT("WS",K8), REPT("EF",L8), IF(OR(M8="",M8=0),"",REPT(IF(M8>0,"ZU","ZM"),ABS(M8))), IF(D8="FW","XXFW",IF(D8="BIO","XXBI",IF(D8="ABWWP","XXWP",IF(D8="WP","XXWP",IF(D8="GG","XXGG",""))))) ) -> BP | AA8: =CHAR(34)&VLOOKUP(Table1[[#This Row],[Name]],'Massnahmenkarten Texte'!A:C,3,FALSE)&CHAR(34) -> "Effizienteste Haushaltsgeräte können den dStromverbrauch deutlich reduzieren"
A9: Flexibles Lastmanagement | B9: *Flexibilität | C9: 1 | E9: 0 | G9: =Table1[[#This Row],[REAL Sofort CO2]]/kgemission_per_sp -> 0 | H9: =Table1[[#This Row],[REAL Strombedarf]]/real_zu_spiel_strombedarf -> 1 | I9: =Table1[[#This Row],[REAL Stromproduktion]]/real_zu_spiel_stromproduktion -> 0 | J9: =Table1[[#This Row],[REAL Stromspeicher]]/real_zu_spiel_stromspeicher -> 4 | M9: -1 | R9: 5 | T9: 20 | Z9: =_xlfn.TEXTJOIN( "XX", TRUE, IF(OR(F9="",F9=0),"",REPT(IF(F9>0,"EN","EM"),ABS(F9))), IF(OR(H9="",H9=0),"",REPT(IF(H9>0,"BM","BP"),ABS(H9))), REPT("SP",I9), REPT("FL",J9), REPT("WS",K9), REPT("EF",L9), IF(OR(M9="",M9=0),"",REPT(IF(M9>0,"ZU","ZM"),ABS(M9))), IF(D9="FW","XXFW",IF(D9="BIO","XXBI",IF(D9="ABWWP","XXWP",IF(D9="WP","XXWP",IF(D9="GG","XXGG",""))))) ) -> BMXXFLFLFLFLXXZM | AA9: =CHAR(34)&VLOOKUP(Table1[[#This Row],[Name]],'Massnahmenkarten Texte'!A:C,3,FALSE)&CHAR(34) -> "Wenn die Nutzer mitspielen, können Verbraucher wie Waschmaschinen oder Geschirrspüler dann einschalten, wenn Erneuerbare zur Verfügung stehen."
A10: Grosser Batteriespeicher | B10: *Flexibilität | C10: 1 | E10: 2 | G10: =Table1[[#This Row],[REAL Sofort CO2]]/kgemission_per_sp -> 0 | H10: =Table1[[#This Row],[REAL Strombedarf]]/real_zu_spiel_strombedarf -> 0 | I10: =Table1[[#This Row],[REAL Stromproduktion]]/real_zu_spiel_stromproduktion -> 0 | J10: =Table1[[#This Row],[REAL Stromspeicher]]/real_zu_spiel_stromspeicher -> 5 | R10: 0 | T10: 25 | W10: Name | Y10: Kleiner Heimspeicher | Z10: =_xlfn.TEXTJOIN( "XX", TRUE, IF(OR(F10="",F10=0),"",REPT(IF(F10>0,"EN","EM"),ABS(F10))), IF(OR(H10="",H10=0),"",REPT(IF(H10>0,"BM","BP"),ABS(H10))), REPT("SP",I10), REPT("FL",J10), REPT("WS",K10), REPT("EF",L10), IF(OR(M10="",M10=0),"",REPT(IF(M10>0,"ZU","ZM"),ABS(M10))), IF(D10="FW","XXFW",IF(D10="BIO","XXBI",IF(D10="ABWWP","XXWP",IF(D10="WP","XXWP",IF(D10="GG","XXGG",""))))) ) -> FLFLFLFLFL | AA10: =CHAR(34)&VLOOKUP(Table1[[#This Row],[Name]],'Massnahmenkarten Texte'!A:C,3,FALSE)&CHAR(34) -> "Batteriespeicher werden immer günstiger. Sie können den eigenen PV-Strom in den Abend retten und vermeiden so dreckigeren Netzbezug."
A11: Kleiner Heimspeicher | B11: *Flexibilität | C11: 1 | E11: 1 | G11: =Table1[[#This Row],[REAL Sofort CO2]]/kgemission_per_sp -> 0 | H11: =Table1[[#This Row],[REAL Strombedarf]]/real_zu_spiel_strombedarf -> 0 | I11: =Table1[[#This Row],[REAL Stromproduktion]]/real_zu_spiel_stromproduktion -> 0 | J11: =Table1[[#This Row],[REAL Stromspeicher]]/real_zu_spiel_stromspeicher -> 2 | T11: 10 | W11: Name | Y11: Grosser Batteriespeicher | Z11: =_xlfn.TEXTJOIN( "XX", TRUE, IF(OR(F11="",F11=0),"",REPT(IF(F11>0,"EN","EM"),ABS(F11))), IF(OR(H11="",H11=0),"",REPT(IF(H11>0,"BM","BP"),ABS(H11))), REPT("SP",I11), REPT("FL",J11), REPT("WS",K11), REPT("EF",L11), IF(OR(M11="",M11=0),"",REPT(IF(M11>0,"ZU","ZM"),ABS(M11))), IF(D11="FW","XXFW",IF(D11="BIO","XXBI",IF(D11="ABWWP","XXWP",IF(D11="WP","XXWP",IF(D11="GG","XXGG",""))))) ) -> FLFL | AA11: =CHAR(34)&VLOOKUP(Table1[[#This Row],[Name]],'Massnahmenkarten Texte'!A:C,3,FALSE)&CHAR(34) -> "Batteriespeicher werden immer günstiger. Sie können den eigenen PV-Strom in den Abend retten und vermeiden so dreckigeren Netzbezug."
A12: Thermische Flexibilität | B12: *Flexibilität | C12: 1 | E12: 0 | G12: =Table1[[#This Row],[REAL Sofort CO2]]/kgemission_per_sp -> 0 | H12: =Table1[[#This Row],[REAL Strombedarf]]/real_zu_spiel_strombedarf -> 0 | I12: =Table1[[#This Row],[REAL Stromproduktion]]/real_zu_spiel_stromproduktion -> 0 | J12: =Table1[[#This Row],[REAL Stromspeicher]]/real_zu_spiel_stromspeicher -> 2 | M12: -1 | T12: 10 | W12: Heizsystem | X12: WP | Z12: =_xlfn.TEXTJOIN( "XX", TRUE, IF(OR(F12="",F12=0),"",REPT(IF(F12>0,"EN","EM"),ABS(F12))), IF(OR(H12="",H12=0),"",REPT(IF(H12>0,"BM","BP"),ABS(H12))), REPT("SP",I12), REPT("FL",J12), REPT("WS",K12), REPT("EF",L12), IF(OR(M12="",M12=0),"",REPT(IF(M12>0,"ZU","ZM"),ABS(M12))), IF(D12="FW","XXFW",IF(D12="BIO","XXBI",IF(D12="ABWWP","XXWP",IF(D12="WP","XXWP",IF(D12="GG","XXGG",""))))) ) -> FLFLXXZM | AA12: =CHAR(34)&VLOOKUP(Table1[[#This Row],[Name]],'Massnahmenkarten Texte'!A:C,3,FALSE)&CHAR(34) -> "Wenn die Nutzer es zulassen, können Wärmepumpen zusätzlichen Strom im Gebäude als Wärme (oder im Sommer durch zusätzliche Kühlung) speichern. So lassen sich noch mehr Erneuerbare einsetzen."
A13: Balkon-Einbau | B13: *Zufriedenheit | C13: 1 | E13: 1 | G13: =Table1[[#This Row],[REAL Sofort CO2]]/kgemission_per_sp -> 10 | H13: =Table1[[#This Row],[REAL Strombedarf]]/real_zu_spiel_strombedarf -> 0 | I13: =Table1[[#This Row],[REAL Stromproduktion]]/real_zu_spiel_stromproduktion -> 0 | J13: =Table1[[#This Row],[REAL Stromspeicher]]/real_zu_spiel_stromspeicher -> 0 | M13: 1 | Q13: 10 | Z13: =_xlfn.TEXTJOIN( "XX", TRUE, IF(OR(F13="",F13=0),"",REPT(IF(F13>0,"EN","EM"),ABS(F13))), IF(OR(H13="",H13=0),"",REPT(IF(H13>0,"BM","BP"),ABS(H13))), REPT("SP",I13), REPT("FL",J13), REPT("WS",K13), REPT("EF",L13), IF(OR(M13="",M13=0),"",REPT(IF(M13>0,"ZU","ZM"),ABS(M13))), IF(D13="FW","XXFW",IF(D13="BIO","XXBI",IF(D13="ABWWP","XXWP",IF(D13="WP","XXWP",IF(D13="GG","XXGG",""))))) ) -> ZU | AA13: =CHAR(34)&VLOOKUP(Table1[[#This Row],[Name]],'Massnahmenkarten Texte'!A:C,3,FALSE)&CHAR(34) -> "Ein Balkon erhöht die Wohnqualität und schafft privaten Freiraum im Bestand. Er bringt Zufriedenheit, verursacht aber zusätzliche Kosten und etwas graue Emissionen durch die neue Konstruktion."
A14: Barrierefreier Zugang | B14: *Zufriedenheit | C14: 1 | E14: 1 | G14: =Table1[[#This Row],[REAL Sofort CO2]]/kgemission_per_sp -> 0 | H14: =Table1[[#This Row],[REAL Strombedarf]]/real_zu_spiel_strombedarf -> 0 | I14: =Table1[[#This Row],[REAL Stromproduktion]]/real_zu_spiel_stromproduktion -> 0 | J14: =Table1[[#This Row],[REAL Stromspeicher]]/real_zu_spiel_stromspeicher -> 0 | M14: 1 | Z14: =_xlfn.TEXTJOIN( "XX", TRUE, IF(OR(F14="",F14=0),"",REPT(IF(F14>0,"EN","EM"),ABS(F14))), IF(OR(H14="",H14=0),"",REPT(IF(H14>0,"BM","BP"),ABS(H14))), REPT("SP",I14), REPT("FL",J14), REPT("WS",K14), REPT("EF",L14), IF(OR(M14="",M14=0),"",REPT(IF(M14>0,"ZU","ZM"),ABS(M14))), IF(D14="FW","XXFW",IF(D14="BIO","XXBI",IF(D14="ABWWP","XXWP",IF(D14="WP","XXWP",IF(D14="GG","XXGG",""))))) ) -> ZU | AA14: =CHAR(34)&VLOOKUP(Table1[[#This Row],[Name]],'Massnahmenkarten Texte'!A:C,3,FALSE)&CHAR(34) -> "Ein barrierefreier Zugang macht das Gebäude für alle einfacher und sicherer nutzbar, besonders mit Kinderwagen, Rollstuhl oder Gehhilfe. Er erhöht die Nutzerzufriedenheit spürbar, verursacht aber je nach Bestand baulichen Aufwand und Kosten."
A15: E-Car Lade-Infrastruktur | B15: *Zufriedenheit | C15: 1 | E15: 1 | G15: =Table1[[#This Row],[REAL Sofort CO2]]/kgemission_per_sp -> 0 | H15: =Table1[[#This Row],[REAL Strombedarf]]/real_zu_spiel_strombedarf -> 4 | I15: =Table1[[#This Row],[REAL Stromproduktion]]/real_zu_spiel_stromproduktion -> 0 | J15: =Table1[[#This Row],[REAL Stromspeicher]]/real_zu_spiel_stromspeicher -> 6 | M15: 1 | R15: 20 | T15: 30 | Z15: =_xlfn.TEXTJOIN( "XX", TRUE, IF(OR(F15="",F15=0),"",REPT(IF(F15>0,"EN","EM"),ABS(F15))), IF(OR(H15="",H15=0),"",REPT(IF(H15>0,"BM","BP"),ABS(H15))), REPT("SP",I15), REPT("FL",J15), REPT("WS",K15), REPT("EF",L15), IF(OR(M15="",M15=0),"",REPT(IF(M15>0,"ZU","ZM"),ABS(M15))), IF(D15="FW","XXFW",IF(D15="BIO","XXBI",IF(D15="ABWWP","XXWP",IF(D15="WP","XXWP",IF(D15="GG","XXGG",""))))) ) -> BMBMBMBMXXFLFLFLFLFLFLXXZU | AA15: =CHAR(34)&VLOOKUP(Table1[[#This Row],[Name]],'Massnahmenkarten Texte'!A:C,3,FALSE)&CHAR(34) -> "Ladepunkte machen das Gebäude attraktiver für Nutzer:innen mit E-Autos. Sie steigern den Strombedarf, können aber auch als flexible Speichermöglichkeit genutzt werden (in Kombination mit "Bi-Direktionalem Laden")."
A16: Fassadenbegrünung | B16: *Zufriedenheit | C16: 1 | E16: 2 | F16: 0 | G16: =Table1[[#This Row],[REAL Sofort CO2]]/kgemission_per_sp -> 0 | H16: =Table1[[#This Row],[REAL Strombedarf]]/real_zu_spiel_strombedarf -> 0 | I16: =Table1[[#This Row],[REAL Stromproduktion]]/real_zu_spiel_stromproduktion -> 0 | J16: =Table1[[#This Row],[REAL Stromspeicher]]/real_zu_spiel_stromspeicher -> 0 | M16: 1 | R16: 0 | W16: Name | Y16: Fassadenintegrierte PV | Z16: =_xlfn.TEXTJOIN( "XX", TRUE, IF(OR(F16="",F16=0),"",REPT(IF(F16>0,"EN","EM"),ABS(F16))), IF(OR(H16="",H16=0),"",REPT(IF(H16>0,"BM","BP"),ABS(H16))), REPT("SP",I16), REPT("FL",J16), REPT("WS",K16), REPT("EF",L16), IF(OR(M16="",M16=0),"",REPT(IF(M16>0,"ZU","ZM"),ABS(M16))), IF(D16="FW","XXFW",IF(D16="BIO","XXBI",IF(D16="ABWWP","XXWP",IF(D16="WP","XXWP",IF(D16="GG","XXGG",""))))) ) -> ZU | AA16: =CHAR(34)&VLOOKUP(Table1[[#This Row],[Name]],'Massnahmenkarten Texte'!A:C,3,FALSE)&CHAR(34) -> "Begrünte Fassaden verbessern das Mikroklima, spenden Schatten und machen das Gebäude attraktiver. Sie erhöhen die Nutzerzufriedenheit leicht und helfen, Emissionen durch geringeren Kühlbedarf etwas zu senken."
A17: Intensive Dachbegrünung | B17: *Zufriedenheit | C17: 1 | E17: 2 | F17: -1 | G17: =Table1[[#This Row],[REAL Sofort CO2]]/kgemission_per_sp -> 0 | H17: =Table1[[#This Row],[REAL Strombedarf]]/real_zu_spiel_strombedarf -> 0 | I17: =Table1[[#This Row],[REAL Stromproduktion]]/real_zu_spiel_stromproduktion -> 0 | J17: =Table1[[#This Row],[REAL Stromspeicher]]/real_zu_spiel_stromspeicher -> 0 | K17: 1 | R17: 0 | U17: 1 | Z17: =_xlfn.TEXTJOIN( "XX", TRUE, IF(OR(F17="",F17=0),"",REPT(IF(F17>0,"EN","EM"),ABS(F17))), IF(OR(H17="",H17=0),"",REPT(IF(H17>0,"BM","BP"),ABS(H17))), REPT("SP",I17), REPT("FL",J17), REPT("WS",K17), REPT("EF",L17), IF(OR(M17="",M17=0),"",REPT(IF(M17>0,"ZU","ZM"),ABS(M17))), IF(D17="FW","XXFW",IF(D17="BIO","XXBI",IF(D17="ABWWP","XXWP",IF(D17="WP","XXWP",IF(D17="GG","XXGG",""))))) ) -> EMXXWS | AA17: =CHAR(34)&VLOOKUP(Table1[[#This Row],[Name]],'Massnahmenkarten Texte'!A:C,3,FALSE)&CHAR(34) -> "Substrat für grosse Pflanzen und Bäume. Bietet etwas Kohlenstoffspeicherung und Wärmeschutz, dafür aufwendiger in der Pflege."
A18: Lift-Einbau | B18: *Zufriedenheit | C18: 1 | E18: 2 | G18: =Table1[[#This Row],[REAL Sofort CO2]]/kgemission_per_sp -> 10 | H18: =Table1[[#This Row],[REAL Strombedarf]]/real_zu_spiel_strombedarf -> 1 | I18: =Table1[[#This Row],[REAL Stromproduktion]]/real_zu_spiel_stromproduktion -> 0 | J18: =Table1[[#This Row],[REAL Stromspeicher]]/real_zu_spiel_stromspeicher -> 0 | M18: 2 | Q18: 10 | R18: 5 | Z18: =_xlfn.TEXTJOIN( "XX", TRUE, IF(OR(F18="",F18=0),"",REPT(IF(F18>0,"EN","EM"),ABS(F18))), IF(OR(H18="",H18=0),"",REPT(IF(H18>0,"BM","BP"),ABS(H18))), REPT("SP",I18), REPT("FL",J18), REPT("WS",K18), REPT("EF",L18), IF(OR(M18="",M18=0),"",REPT(IF(M18>0,"ZU","ZM"),ABS(M18))), IF(D18="FW","XXFW",IF(D18="BIO","XXBI",IF(D18="ABWWP","XXWP",IF(D18="WP","XXWP",IF(D18="GG","XXGG",""))))) ) -> BMXXZUZU | AA18: =CHAR(34)&VLOOKUP(Table1[[#This Row],[Name]],'Massnahmenkarten Texte'!A:C,3,FALSE)&CHAR(34) -> "Ein Lift macht das Gebäude komfortabler und auch im Alter oder bei eingeschränkter Mobilität gut nutzbar. Er bringt viel Nutzerzufriedenheit, ist aber teuer und erfordert größere bauliche Eingriffe."
A19: Außenliegender Sonnenschutz | B19: *Zufriedenheit | C19: 1 | E19: 1 | G19: =Table1[[#This Row],[REAL Sofort CO2]]/kgemission_per_sp -> 0 | H19: =Table1[[#This Row],[REAL Strombedarf]]/real_zu_spiel_strombedarf -> 0 | I19: =Table1[[#This Row],[REAL Stromproduktion]]/real_zu_spiel_stromproduktion -> 0 | J19: =Table1[[#This Row],[REAL Stromspeicher]]/real_zu_spiel_stromspeicher -> 0 | M19: 1 | V19: 1 | Z19: =_xlfn.TEXTJOIN( "XX", TRUE, IF(OR(F19="",F19=0),"",REPT(IF(F19>0,"EN","EM"),ABS(F19))), IF(OR(H19="",H19=0),"",REPT(IF(H19>0,"BM","BP"),ABS(H19))), REPT("SP",I19), REPT("FL",J19), REPT("WS",K19), REPT("EF",L19), IF(OR(M19="",M19=0),"",REPT(IF(M19>0,"ZU","ZM"),ABS(M19))), IF(D19="FW","XXFW",IF(D19="BIO","XXBI",IF(D19="ABWWP","XXWP",IF(D19="WP","XXWP",IF(D19="GG","XXGG",""))))) ) -> ZU | AA19: =CHAR(34)&VLOOKUP(Table1[[#This Row],[Name]],'Massnahmenkarten Texte'!A:C,3,FALSE)&CHAR(34) -> "Reduziert die Sonneneinstrahlung und damit die nötige Kühlenergie im Sommer."
A20: Deckenheizung | B20: Abgabe | C20: 1 | E20: 2 | G20: =Table1[[#This Row],[REAL Sofort CO2]]/kgemission_per_sp -> 0 | H20: =Table1[[#This Row],[REAL Strombedarf]]/real_zu_spiel_strombedarf -> 0 | I20: =Table1[[#This Row],[REAL Stromproduktion]]/real_zu_spiel_stromproduktion -> 0 | J20: =Table1[[#This Row],[REAL Stromspeicher]]/real_zu_spiel_stromspeicher -> 0 | L20: 2 | R20: 0 | V20: 2 | Z20: =_xlfn.TEXTJOIN( "XX", TRUE, IF(OR(F20="",F20=0),"",REPT(IF(F20>0,"EN","EM"),ABS(F20))), IF(OR(H20="",H20=0),"",REPT(IF(H20>0,"BM","BP"),ABS(H20))), REPT("SP",I20), REPT("FL",J20), REPT("WS",K20), REPT("EF",L20), IF(OR(M20="",M20=0),"",REPT(IF(M20>0,"ZU","ZM"),ABS(M20))), IF(D20="FW","XXFW",IF(D20="BIO","XXBI",IF(D20="ABWWP","XXWP",IF(D20="WP","XXWP",IF(D20="GG","XXGG",""))))) ) -> EFEF | AA20: =CHAR(34)&VLOOKUP(Table1[[#This Row],[Name]],'Massnahmenkarten Texte'!A:C,3,FALSE)&CHAR(34) -> "Eine Deckenheizung gibt Wärme über große Flächen ab und ermöglicht niedrige Vorlauftemperaturen. Dadurch arbeiten Wärmepumpen effizienter, während Planung, Regelung und Nutzerakzeptanz gut gelöst werden müssen."
A21: Fussbodenheizung | B21: Abgabe | C21: 1 | E21: 3 | G21: =Table1[[#This Row],[REAL Sofort CO2]]/kgemission_per_sp -> 0 | H21: =Table1[[#This Row],[REAL Strombedarf]]/real_zu_spiel_strombedarf -> 0 | I21: =Table1[[#This Row],[REAL Stromproduktion]]/real_zu_spiel_stromproduktion -> 0 | J21: =Table1[[#This Row],[REAL Stromspeicher]]/real_zu_spiel_stromspeicher -> 0 | L21: 2 | M21: 1 | R21: 0 | V21: 2 | Z21: =_xlfn.TEXTJOIN( "XX", TRUE, IF(OR(F21="",F21=0),"",REPT(IF(F21>0,"EN","EM"),ABS(F21))), IF(OR(H21="",H21=0),"",REPT(IF(H21>0,"BM","BP"),ABS(H21))), REPT("SP",I21), REPT("FL",J21), REPT("WS",K21), REPT("EF",L21), IF(OR(M21="",M21=0),"",REPT(IF(M21>0,"ZU","ZM"),ABS(M21))), IF(D21="FW","XXFW",IF(D21="BIO","XXBI",IF(D21="ABWWP","XXWP",IF(D21="WP","XXWP",IF(D21="GG","XXGG",""))))) ) -> EFEFXXZU | AA21: =CHAR(34)&VLOOKUP(Table1[[#This Row],[Name]],'Massnahmenkarten Texte'!A:C,3,FALSE)&CHAR(34) -> "Eine Fußbodenheizung gibt Wärme über große Flächen ab, ist komfortabel und ermöglicht niedrige Vorlauftemperaturen. Dadurch arbeiten Wärmepumpen effizienter; im Bestand sind aber Bodenaufbau, Bauaufwand und die eher träge Regelung zu beachten."
A22: Niedertemperatur Radiator | B22: Abgabe | C22: 1 | E22: 0 | G22: =Table1[[#This Row],[REAL Sofort CO2]]/kgemission_per_sp -> 0 | H22: =Table1[[#This Row],[REAL Strombedarf]]/real_zu_spiel_strombedarf -> 0 | I22: =Table1[[#This Row],[REAL Stromproduktion]]/real_zu_spiel_stromproduktion -> 0 | J22: =Table1[[#This Row],[REAL Stromspeicher]]/real_zu_spiel_stromspeicher -> 0 | L22: 1 | R22: 0 | V22: 1 | Z22: =_xlfn.TEXTJOIN( "XX", TRUE, IF(OR(F22="",F22=0),"",REPT(IF(F22>0,"EN","EM"),ABS(F22))), IF(OR(H22="",H22=0),"",REPT(IF(H22>0,"BM","BP"),ABS(H22))), REPT("SP",I22), REPT("FL",J22), REPT("WS",K22), REPT("EF",L22), IF(OR(M22="",M22=0),"",REPT(IF(M22>0,"ZU","ZM"),ABS(M22))), IF(D22="FW","XXFW",IF(D22="BIO","XXBI",IF(D22="ABWWP","XXWP",IF(D22="WP","XXWP",IF(D22="GG","XXGG",""))))) ) -> EF | AA22: =CHAR(34)&VLOOKUP(Table1[[#This Row],[Name]],'Massnahmenkarten Texte'!A:C,3,FALSE)&CHAR(34) -> "Niedertemperatur-Radiatoren sind eine günstigere Alternative zu Flächenheizungen und lassen sich im Bestand meist einfacher nachrüsten. Sie ermöglichen niedrigere Vorlauftemperaturen und verbessern damit die Effizienz der Wärmepumpe, bieten aber weniger Komfort und Effizienzpotenzial als Fußboden- oder Deckenheizung."
A23: Radiatoren mit Lüftern | B23: Abgabe | C23: 1 | E23: 1 | G23: =Table1[[#This Row],[REAL Sofort CO2]]/kgemission_per_sp -> 0 | H23: =Table1[[#This Row],[REAL Strombedarf]]/real_zu_spiel_strombedarf -> 0 | I23: =Table1[[#This Row],[REAL Stromproduktion]]/real_zu_spiel_stromproduktion -> 0 | J23: =Table1[[#This Row],[REAL Stromspeicher]]/real_zu_spiel_stromspeicher -> 0 | L23: 2 | M23: -1 | R23: 0 | V23: 2 | Z23: =_xlfn.TEXTJOIN( "XX", TRUE, IF(OR(F23="",F23=0),"",REPT(IF(F23>0,"EN","EM"),ABS(F23))), IF(OR(H23="",H23=0),"",REPT(IF(H23>0,"BM","BP"),ABS(H23))), REPT("SP",I23), REPT("FL",J23), REPT("WS",K23), REPT("EF",L23), IF(OR(M23="",M23=0),"",REPT(IF(M23>0,"ZU","ZM"),ABS(M23))), IF(D23="FW","XXFW",IF(D23="BIO","XXBI",IF(D23="ABWWP","XXWP",IF(D23="WP","XXWP",IF(D23="GG","XXGG",""))))) ) -> EFEFXXZM | AA23: =CHAR(34)&VLOOKUP(Table1[[#This Row],[Name]],'Massnahmenkarten Texte'!A:C,3,FALSE)&CHAR(34) -> "Radiatoren mit Lüftern erhöhen die Wärmeabgabe und können auch bei niedrigeren Vorlauftemperaturen gut funktionieren. Sie sind einfach nachzurüsten, können aber durch Geräusche oder Luftbewegung als störend empfunden werden."
A24: TestMassnahme | B24: Abgabe | C24: 0 | E24: 999 | G24: =Table1[[#This Row],[REAL Sofort CO2]]/kgemission_per_sp -> 0 | H24: =Table1[[#This Row],[REAL Strombedarf]]/real_zu_spiel_strombedarf -> 1 | I24: =Table1[[#This Row],[REAL Stromproduktion]]/real_zu_spiel_stromproduktion -> 0 | J24: =Table1[[#This Row],[REAL Stromspeicher]]/real_zu_spiel_stromspeicher -> 1 | K24: 1 | L24: 1 | M24: 1 | R24: 5 | T24: 5 | U24: 1 | V24: 1 | Z24: =_xlfn.TEXTJOIN( "XX", TRUE, IF(OR(F24="",F24=0),"",REPT(IF(F24>0,"EN","EM"),ABS(F24))), IF(OR(H24="",H24=0),"",REPT(IF(H24>0,"BM","BP"),ABS(H24))), REPT("SP",I24), REPT("FL",J24), REPT("WS",K24), REPT("EF",L24), IF(OR(M24="",M24=0),"",REPT(IF(M24>0,"ZU","ZM"),ABS(M24))), IF(D24="FW","XXFW",IF(D24="BIO","XXBI",IF(D24="ABWWP","XXWP",IF(D24="WP","XXWP",IF(D24="GG","XXGG",""))))) ) -> BMXXFLXXWSXXEFXXZU | AA24: =CHAR(34)&VLOOKUP(Table1[[#This Row],[Name]],'Massnahmenkarten Texte'!A:C,3,FALSE)&CHAR(34) -> "Eine Beschreibung hier einfügen, kurz halten oder sie wird abgeschnitten"
A25: Wandheizung | B25: Abgabe | C25: 1 | E25: 2 | G25: =Table1[[#This Row],[REAL Sofort CO2]]/kgemission_per_sp -> 0 | H25: =Table1[[#This Row],[REAL Strombedarf]]/real_zu_spiel_strombedarf -> 0 | I25: =Table1[[#This Row],[REAL Stromproduktion]]/real_zu_spiel_stromproduktion -> 0 | J25: =Table1[[#This Row],[REAL Stromspeicher]]/real_zu_spiel_stromspeicher -> 0 | L25: 2 | R25: 0 | V25: 2 | Z25: =_xlfn.TEXTJOIN( "XX", TRUE, IF(OR(F25="",F25=0),"",REPT(IF(F25>0,"EN","EM"),ABS(F25))), IF(OR(H25="",H25=0),"",REPT(IF(H25>0,"BM","BP"),ABS(H25))), REPT("SP",I25), REPT("FL",J25), REPT("WS",K25), REPT("EF",L25), IF(OR(M25="",M25=0),"",REPT(IF(M25>0,"ZU","ZM"),ABS(M25))), IF(D25="FW","XXFW",IF(D25="BIO","XXBI",IF(D25="ABWWP","XXWP",IF(D25="WP","XXWP",IF(D25="GG","XXGG",""))))) ) -> EFEF | AA25: =CHAR(34)&VLOOKUP(Table1[[#This Row],[Name]],'Massnahmenkarten Texte'!A:C,3,FALSE)&CHAR(34) -> "Eine Wandheizung gibt Wärme über große Flächen ab, ist komfortabel und ermöglicht niedrige Vorlauftemperaturen. Dadurch arbeiten Wärmepumpen effizienter; im Bestand sind aber Einbauaufwand, freie Wandflächen und spätere Möblierung zu beachten."
A26: Dachgärten | B26: Dachnutzung | C26: 1 | E26: 2 | F26: -1 | G26: =Table1[[#This Row],[REAL Sofort CO2]]/kgemission_per_sp -> 0 | H26: =Table1[[#This Row],[REAL Strombedarf]]/real_zu_spiel_strombedarf -> 0 | I26: =Table1[[#This Row],[REAL Stromproduktion]]/real_zu_spiel_stromproduktion -> 0 | J26: =Table1[[#This Row],[REAL Stromspeicher]]/real_zu_spiel_stromspeicher -> 0 | M26: 1 | R26: 0 | Z26: =_xlfn.TEXTJOIN( "XX", TRUE, IF(OR(F26="",F26=0),"",REPT(IF(F26>0,"EN","EM"),ABS(F26))), IF(OR(H26="",H26=0),"",REPT(IF(H26>0,"BM","BP"),ABS(H26))), REPT("SP",I26), REPT("FL",J26), REPT("WS",K26), REPT("EF",L26), IF(OR(M26="",M26=0),"",REPT(IF(M26>0,"ZU","ZM"),ABS(M26))), IF(D26="FW","XXFW",IF(D26="BIO","XXBI",IF(D26="ABWWP","XXWP",IF(D26="WP","XXWP",IF(D26="GG","XXGG",""))))) ) -> EMXXZU | AA26: =CHAR(34)&VLOOKUP(Table1[[#This Row],[Name]],'Massnahmenkarten Texte'!A:C,3,FALSE)&CHAR(34) -> "Bepflanzte Grünflächen, die auf dem Dach eines Gebäudes angelegt wurden, um ökologische Vorteile und einen höheren Wohnkomfort zu bieten."
A27: Grosse Dach-PV-Anlage | B27: Dachnutzung | C27: 1 | E27: 3 | G27: =Table1[[#This Row],[REAL Sofort CO2]]/kgemission_per_sp -> 0 | H27: =Table1[[#This Row],[REAL Strombedarf]]/real_zu_spiel_strombedarf -> 0 | I27: =Table1[[#This Row],[REAL Stromproduktion]]/real_zu_spiel_stromproduktion -> 8 | J27: =Table1[[#This Row],[REAL Stromspeicher]]/real_zu_spiel_stromspeicher -> 0 | S27: 40 | Z27: =_xlfn.TEXTJOIN( "XX", TRUE, IF(OR(F27="",F27=0),"",REPT(IF(F27>0,"EN","EM"),ABS(F27))), IF(OR(H27="",H27=0),"",REPT(IF(H27>0,"BM","BP"),ABS(H27))), REPT("SP",I27), REPT("FL",J27), REPT("WS",K27), REPT("EF",L27), IF(OR(M27="",M27=0),"",REPT(IF(M27>0,"ZU","ZM"),ABS(M27))), IF(D27="FW","XXFW",IF(D27="BIO","XXBI",IF(D27="ABWWP","XXWP",IF(D27="WP","XXWP",IF(D27="GG","XXGG",""))))) ) -> SPSPSPSPSPSPSPSP | AA27: =CHAR(34)&VLOOKUP(Table1[[#This Row],[Name]],'Massnahmenkarten Texte'!A:C,3,FALSE)&CHAR(34) -> "Eine große PV-Anlage nutzt die verfügbare Dachfläche konsequent und kann viel Emissionen einsparen. Damit der zusätzliche Strom gut genutzt wird, braucht sie meist Speicher oder flexible Verbraucher."
A28: Kleine Dach-PV-Anlage | B28: Dachnutzung | C28: 1 | E28: 1 | G28: =Table1[[#This Row],[REAL Sofort CO2]]/kgemission_per_sp -> 0 | H28: =Table1[[#This Row],[REAL Strombedarf]]/real_zu_spiel_strombedarf -> 0 | I28: =Table1[[#This Row],[REAL Stromproduktion]]/real_zu_spiel_stromproduktion -> 2 | J28: =Table1[[#This Row],[REAL Stromspeicher]]/real_zu_spiel_stromspeicher -> 0 | S28: 10 | Z28: =_xlfn.TEXTJOIN( "XX", TRUE, IF(OR(F28="",F28=0),"",REPT(IF(F28>0,"EN","EM"),ABS(F28))), IF(OR(H28="",H28=0),"",REPT(IF(H28>0,"BM","BP"),ABS(H28))), REPT("SP",I28), REPT("FL",J28), REPT("WS",K28), REPT("EF",L28), IF(OR(M28="",M28=0),"",REPT(IF(M28>0,"ZU","ZM"),ABS(M28))), IF(D28="FW","XXFW",IF(D28="BIO","XXBI",IF(D28="ABWWP","XXWP",IF(D28="WP","XXWP",IF(D28="GG","XXGG",""))))) ) -> SPSP | AA28: =CHAR(34)&VLOOKUP(Table1[[#This Row],[Name]],'Massnahmenkarten Texte'!A:C,3,FALSE)&CHAR(34) -> "Eine kleine PV-Anlage ist die einfache Standardlösung und deckt vor allem den direkten Eigenverbrauch. Sie spart Emissionen ohne zusätzlichen Speicher, bleibt aber in ihrem Potenzial begrenzt."
A29: Mittlere Dach-PV-Anlage | B29: Dachnutzung | C29: 1 | E29: 2 | G29: =Table1[[#This Row],[REAL Sofort CO2]]/kgemission_per_sp -> 0 | H29: =Table1[[#This Row],[REAL Strombedarf]]/real_zu_spiel_strombedarf -> 0 | I29: =Table1[[#This Row],[REAL Stromproduktion]]/real_zu_spiel_stromproduktion -> 4 | J29: =Table1[[#This Row],[REAL Stromspeicher]]/real_zu_spiel_stromspeicher -> 0 | S29: 20 | Z29: =_xlfn.TEXTJOIN( "XX", TRUE, IF(OR(F29="",F29=0),"",REPT(IF(F29>0,"EN","EM"),ABS(F29))), IF(OR(H29="",H29=0),"",REPT(IF(H29>0,"BM","BP"),ABS(H29))), REPT("SP",I29), REPT("FL",J29), REPT("WS",K29), REPT("EF",L29), IF(OR(M29="",M29=0),"",REPT(IF(M29>0,"ZU","ZM"),ABS(M29))), IF(D29="FW","XXFW",IF(D29="BIO","XXBI",IF(D29="ABWWP","XXWP",IF(D29="WP","XXWP",IF(D29="GG","XXGG",""))))) ) -> SPSPSPSP | AA29: =CHAR(34)&VLOOKUP(Table1[[#This Row],[Name]],'Massnahmenkarten Texte'!A:C,3,FALSE)&CHAR(34) -> "Eine mittlere PV-Anlage ist ein guter Kompromiss zwischen Aufwand, Kosten und Klimawirkung. Sie erzeugt mehr Strom als die kleine Variante und wird mit Speicher oder flexiblen Verbrauchern deutlich wirksamer."
A30: PV Dachziegel | B30: Dachnutzung | C30: 1 | E30: 2 | G30: =Table1[[#This Row],[REAL Sofort CO2]]/kgemission_per_sp -> 0 | H30: =Table1[[#This Row],[REAL Strombedarf]]/real_zu_spiel_strombedarf -> 0 | I30: =Table1[[#This Row],[REAL Stromproduktion]]/real_zu_spiel_stromproduktion -> 3 | J30: =Table1[[#This Row],[REAL Stromspeicher]]/real_zu_spiel_stromspeicher -> 0 | S30: 15 | Z30: =_xlfn.TEXTJOIN( "XX", TRUE, IF(OR(F30="",F30=0),"",REPT(IF(F30>0,"EN","EM"),ABS(F30))), IF(OR(H30="",H30=0),"",REPT(IF(H30>0,"BM","BP"),ABS(H30))), REPT("SP",I30), REPT("FL",J30), REPT("WS",K30), REPT("EF",L30), IF(OR(M30="",M30=0),"",REPT(IF(M30>0,"ZU","ZM"),ABS(M30))), IF(D30="FW","XXFW",IF(D30="BIO","XXBI",IF(D30="ABWWP","XXWP",IF(D30="WP","XXWP",IF(D30="GG","XXGG",""))))) ) -> SPSPSP | AA30: =CHAR(34)&VLOOKUP(Table1[[#This Row],[Name]],'Massnahmenkarten Texte'!A:C,3,FALSE)&CHAR(34) -> "Lösung für denkmalgeschützte Dächer mit reduzierter Effizienz im Vergleich zu herkömmlichen Paneelen."
A31: PV-Pergola | B31: Dachnutzung | C31: 1 | E31: 3 | G31: =Table1[[#This Row],[REAL Sofort CO2]]/kgemission_per_sp -> 0 | H31: =Table1[[#This Row],[REAL Strombedarf]]/real_zu_spiel_strombedarf -> 0 | I31: =Table1[[#This Row],[REAL Stromproduktion]]/real_zu_spiel_stromproduktion -> 2 | J31: =Table1[[#This Row],[REAL Stromspeicher]]/real_zu_spiel_stromspeicher -> 0 | M31: 1 | S31: 10 | Z31: =_xlfn.TEXTJOIN( "XX", TRUE, IF(OR(F31="",F31=0),"",REPT(IF(F31>0,"EN","EM"),ABS(F31))), IF(OR(H31="",H31=0),"",REPT(IF(H31>0,"BM","BP"),ABS(H31))), REPT("SP",I31), REPT("FL",J31), REPT("WS",K31), REPT("EF",L31), IF(OR(M31="",M31=0),"",REPT(IF(M31>0,"ZU","ZM"),ABS(M31))), IF(D31="FW","XXFW",IF(D31="BIO","XXBI",IF(D31="ABWWP","XXWP",IF(D31="WP","XXWP",IF(D31="GG","XXGG",""))))) ) -> SPSPXXZU | AA31: =CHAR(34)&VLOOKUP(Table1[[#This Row],[Name]],'Massnahmenkarten Texte'!A:C,3,FALSE)&CHAR(34) -> "Eine PV-Pergola ist eine überdachte Terrasse oder Freifläche, bei der die PV-Module zugleich Schatten spenden und Strom erzeugen. Sie ist aufwendig, erhöht aber die Aufenthaltsqualität und Nutzerzufriedenheit deutlich."
A32: Thermische Solaranlage | B32: Dachnutzung | C32: 1 | E32: 2 | G32: =Table1[[#This Row],[REAL Sofort CO2]]/kgemission_per_sp -> 0 | H32: =Table1[[#This Row],[REAL Strombedarf]]/real_zu_spiel_strombedarf -> 0 | I32: =Table1[[#This Row],[REAL Stromproduktion]]/real_zu_spiel_stromproduktion -> 0 | J32: =Table1[[#This Row],[REAL Stromspeicher]]/real_zu_spiel_stromspeicher -> 0 | K32: 1 | R32: 0 | U32: 1 | Z32: =_xlfn.TEXTJOIN( "XX", TRUE, IF(OR(F32="",F32=0),"",REPT(IF(F32>0,"EN","EM"),ABS(F32))), IF(OR(H32="",H32=0),"",REPT(IF(H32>0,"BM","BP"),ABS(H32))), REPT("SP",I32), REPT("FL",J32), REPT("WS",K32), REPT("EF",L32), IF(OR(M32="",M32=0),"",REPT(IF(M32>0,"ZU","ZM"),ABS(M32))), IF(D32="FW","XXFW",IF(D32="BIO","XXBI",IF(D32="ABWWP","XXWP",IF(D32="WP","XXWP",IF(D32="GG","XXGG",""))))) ) -> WS | AA32: =CHAR(34)&VLOOKUP(Table1[[#This Row],[Name]],'Massnahmenkarten Texte'!A:C,3,FALSE)&CHAR(34) -> "Eine thermische Solaranlage nutzt Sonnenwärme für Warmwasser oder Heizungsunterstützung und reduziert so den Heizenergiebedarf. Früher war sie häufiger die Standardlösung am Dach, heute wird oft PV bevorzugt."
A33: Ambitionierte Sanierung | B33: Dämmung | C33: 1 | E33: 2 | G33: =Table1[[#This Row],[REAL Sofort CO2]]/kgemission_per_sp -> 30 | H33: =Table1[[#This Row],[REAL Strombedarf]]/real_zu_spiel_strombedarf -> 0 | I33: =Table1[[#This Row],[REAL Stromproduktion]]/real_zu_spiel_stromproduktion -> 0 | J33: =Table1[[#This Row],[REAL Stromspeicher]]/real_zu_spiel_stromspeicher -> 0 | K33: 4 | Q33: 30 | R33: 0 | U33: 4 | Z33: =_xlfn.TEXTJOIN( "XX", TRUE, IF(OR(F33="",F33=0),"",REPT(IF(F33>0,"EN","EM"),ABS(F33))), IF(OR(H33="",H33=0),"",REPT(IF(H33>0,"BM","BP"),ABS(H33))), REPT("SP",I33), REPT("FL",J33), REPT("WS",K33), REPT("EF",L33), IF(OR(M33="",M33=0),"",REPT(IF(M33>0,"ZU","ZM"),ABS(M33))), IF(D33="FW","XXFW",IF(D33="BIO","XXBI",IF(D33="ABWWP","XXWP",IF(D33="WP","XXWP",IF(D33="GG","XXGG",""))))) ) -> WSWSWSWS | AA33: =CHAR(34)&VLOOKUP(Table1[[#This Row],[Name]],'Massnahmenkarten Texte'!A:C,3,FALSE)&CHAR(34) -> "Die Gebäudehülle wird über den Mindeststandard hinaus verbessert. Dadurch sinkt der Heizwärmebedarf stärker, jedoch mit etwas höherem Material- und Investitionsaufwand."
A34: Ambitionierte Sanierung ökologisch | B34: Dämmung | C34: 1 | E34: 3 | G34: =Table1[[#This Row],[REAL Sofort CO2]]/kgemission_per_sp -> -10 | H34: =Table1[[#This Row],[REAL Strombedarf]]/real_zu_spiel_strombedarf -> 0 | I34: =Table1[[#This Row],[REAL Stromproduktion]]/real_zu_spiel_stromproduktion -> 0 | J34: =Table1[[#This Row],[REAL Stromspeicher]]/real_zu_spiel_stromspeicher -> 0 | K34: 4 | Q34: -10 | R34: 0 | U34: 4 | Z34: =_xlfn.TEXTJOIN( "XX", TRUE, IF(OR(F34="",F34=0),"",REPT(IF(F34>0,"EN","EM"),ABS(F34))), IF(OR(H34="",H34=0),"",REPT(IF(H34>0,"BM","BP"),ABS(H34))), REPT("SP",I34), REPT("FL",J34), REPT("WS",K34), REPT("EF",L34), IF(OR(M34="",M34=0),"",REPT(IF(M34>0,"ZU","ZM"),ABS(M34))), IF(D34="FW","XXFW",IF(D34="BIO","XXBI",IF(D34="ABWWP","XXWP",IF(D34="WP","XXWP",IF(D34="GG","XXGG",""))))) ) -> WSWSWSWS | AA34: =CHAR(34)&VLOOKUP(Table1[[#This Row],[Name]],'Massnahmenkarten Texte'!A:C,3,FALSE)&CHAR(34) -> "Die Gebäudehülle wird über den Mindeststandard hinaus mit ökologischen Dämmstoffen verbessert. Dadurch sinkt der Heizwärmebedarf stärker."
A35: Dämmputze | B35: Dämmung | C35: 0 | E35: 999 | G35: =Table1[[#This Row],[REAL Sofort CO2]]/kgemission_per_sp -> 0 | H35: =Table1[[#This Row],[REAL Strombedarf]]/real_zu_spiel_strombedarf -> 0 | I35: =Table1[[#This Row],[REAL Stromproduktion]]/real_zu_spiel_stromproduktion -> 0 | J35: =Table1[[#This Row],[REAL Stromspeicher]]/real_zu_spiel_stromspeicher -> 0 | K35: 1 | R35: 0 | U35: 1 | Z35: =_xlfn.TEXTJOIN( "XX", TRUE, IF(OR(F35="",F35=0),"",REPT(IF(F35>0,"EN","EM"),ABS(F35))), IF(OR(H35="",H35=0),"",REPT(IF(H35>0,"BM","BP"),ABS(H35))), REPT("SP",I35), REPT("FL",J35), REPT("WS",K35), REPT("EF",L35), IF(OR(M35="",M35=0),"",REPT(IF(M35>0,"ZU","ZM"),ABS(M35))), IF(D35="FW","XXFW",IF(D35="BIO","XXBI",IF(D35="ABWWP","XXWP",IF(D35="WP","XXWP",IF(D35="GG","XXGG",""))))) ) -> WS | AA35: =CHAR(34)&VLOOKUP(Table1[[#This Row],[Name]],'Massnahmenkarten Texte'!A:C,3,FALSE)&CHAR(34) -> "zu speziell"
A36: Fossile Dämmstoffe | B36: Dämmung | C36: 0 | E36: 999 | G36: =Table1[[#This Row],[REAL Sofort CO2]]/kgemission_per_sp -> 0 | H36: =Table1[[#This Row],[REAL Strombedarf]]/real_zu_spiel_strombedarf -> 0 | I36: =Table1[[#This Row],[REAL Stromproduktion]]/real_zu_spiel_stromproduktion -> 0 | J36: =Table1[[#This Row],[REAL Stromspeicher]]/real_zu_spiel_stromspeicher -> 0 | K36: 2 | R36: 0 | U36: 2 | Z36: =_xlfn.TEXTJOIN( "XX", TRUE, IF(OR(F36="",F36=0),"",REPT(IF(F36>0,"EN","EM"),ABS(F36))), IF(OR(H36="",H36=0),"",REPT(IF(H36>0,"BM","BP"),ABS(H36))), REPT("SP",I36), REPT("FL",J36), REPT("WS",K36), REPT("EF",L36), IF(OR(M36="",M36=0),"",REPT(IF(M36>0,"ZU","ZM"),ABS(M36))), IF(D36="FW","XXFW",IF(D36="BIO","XXBI",IF(D36="ABWWP","XXWP",IF(D36="WP","XXWP",IF(D36="GG","XXGG",""))))) ) -> WSWS | AA36: =CHAR(34)&VLOOKUP(Table1[[#This Row],[Name]],'Massnahmenkarten Texte'!A:C,3,FALSE)&CHAR(34) -> "Mineralische oder synthetische Dämmstoffe. Hohe Umweltauswirkungen."
A37: Fossile Dämmstoffe | B37: Dämmung | C37: 0 | E37: 999 | G37: =Table1[[#This Row],[REAL Sofort CO2]]/kgemission_per_sp -> 0 | H37: =Table1[[#This Row],[REAL Strombedarf]]/real_zu_spiel_strombedarf -> 0 | I37: =Table1[[#This Row],[REAL Stromproduktion]]/real_zu_spiel_stromproduktion -> 0 | J37: =Table1[[#This Row],[REAL Stromspeicher]]/real_zu_spiel_stromspeicher -> 0 | K37: 2 | R37: 0 | U37: 2 | Z37: =_xlfn.TEXTJOIN( "XX", TRUE, IF(OR(F37="",F37=0),"",REPT(IF(F37>0,"EN","EM"),ABS(F37))), IF(OR(H37="",H37=0),"",REPT(IF(H37>0,"BM","BP"),ABS(H37))), REPT("SP",I37), REPT("FL",J37), REPT("WS",K37), REPT("EF",L37), IF(OR(M37="",M37=0),"",REPT(IF(M37>0,"ZU","ZM"),ABS(M37))), IF(D37="FW","XXFW",IF(D37="BIO","XXBI",IF(D37="ABWWP","XXWP",IF(D37="WP","XXWP",IF(D37="GG","XXGG",""))))) ) -> WSWS | AA37: =CHAR(34)&VLOOKUP(Table1[[#This Row],[Name]],'Massnahmenkarten Texte'!A:C,3,FALSE)&CHAR(34) -> "Mineralische oder synthetische Dämmstoffe. Hohe Umweltauswirkungen."
A38: Holzfaserdämmung | B38: Dämmung | C38: 0 | E38: 999 | G38: =Table1[[#This Row],[REAL Sofort CO2]]/kgemission_per_sp -> 0 | H38: =Table1[[#This Row],[REAL Strombedarf]]/real_zu_spiel_strombedarf -> 0 | I38: =Table1[[#This Row],[REAL Stromproduktion]]/real_zu_spiel_stromproduktion -> 0 | J38: =Table1[[#This Row],[REAL Stromspeicher]]/real_zu_spiel_stromspeicher -> 0 | K38: 2 | R38: 0 | U38: 2 | Z38: =_xlfn.TEXTJOIN( "XX", TRUE, IF(OR(F38="",F38=0),"",REPT(IF(F38>0,"EN","EM"),ABS(F38))), IF(OR(H38="",H38=0),"",REPT(IF(H38>0,"BM","BP"),ABS(H38))), REPT("SP",I38), REPT("FL",J38), REPT("WS",K38), REPT("EF",L38), IF(OR(M38="",M38=0),"",REPT(IF(M38>0,"ZU","ZM"),ABS(M38))), IF(D38="FW","XXFW",IF(D38="BIO","XXBI",IF(D38="ABWWP","XXWP",IF(D38="WP","XXWP",IF(D38="GG","XXGG",""))))) ) -> WSWS | AA38: =CHAR(34)&VLOOKUP(Table1[[#This Row],[Name]],'Massnahmenkarten Texte'!A:C,3,FALSE)&CHAR(34) -> "Natürlicher Dämmstoff. Geringe Umweltbelastung und recyclebar."
A39: Holzfaserdämmung | B39: Dämmung | C39: 0 | E39: 999 | G39: =Table1[[#This Row],[REAL Sofort CO2]]/kgemission_per_sp -> 0 | H39: =Table1[[#This Row],[REAL Strombedarf]]/real_zu_spiel_strombedarf -> 0 | I39: =Table1[[#This Row],[REAL Stromproduktion]]/real_zu_spiel_stromproduktion -> 0 | J39: =Table1[[#This Row],[REAL Stromspeicher]]/real_zu_spiel_stromspeicher -> 0 | K39: 2 | R39: 0 | U39: 2 | Z39: =_xlfn.TEXTJOIN( "XX", TRUE, IF(OR(F39="",F39=0),"",REPT(IF(F39>0,"EN","EM"),ABS(F39))), IF(OR(H39="",H39=0),"",REPT(IF(H39>0,"BM","BP"),ABS(H39))), REPT("SP",I39), REPT("FL",J39), REPT("WS",K39), REPT("EF",L39), IF(OR(M39="",M39=0),"",REPT(IF(M39>0,"ZU","ZM"),ABS(M39))), IF(D39="FW","XXFW",IF(D39="BIO","XXBI",IF(D39="ABWWP","XXWP",IF(D39="WP","XXWP",IF(D39="GG","XXGG",""))))) ) -> WSWS | AA39: =CHAR(34)&VLOOKUP(Table1[[#This Row],[Name]],'Massnahmenkarten Texte'!A:C,3,FALSE)&CHAR(34) -> "Natürlicher Dämmstoff. Geringe Umweltbelastung und recyclebar."
A40: Passivhaussanierung konventionell | B40: Dämmung | C40: 1 | E40: 3 | G40: =Table1[[#This Row],[REAL Sofort CO2]]/kgemission_per_sp -> 40 | H40: =Table1[[#This Row],[REAL Strombedarf]]/real_zu_spiel_strombedarf -> 0 | I40: =Table1[[#This Row],[REAL Stromproduktion]]/real_zu_spiel_stromproduktion -> 0 | J40: =Table1[[#This Row],[REAL Stromspeicher]]/real_zu_spiel_stromspeicher -> 0 | K40: 5 | Q40: 40 | R40: 0 | U40: 5 | Z40: =_xlfn.TEXTJOIN( "XX", TRUE, IF(OR(F40="",F40=0),"",REPT(IF(F40>0,"EN","EM"),ABS(F40))), IF(OR(H40="",H40=0),"",REPT(IF(H40>0,"BM","BP"),ABS(H40))), REPT("SP",I40), REPT("FL",J40), REPT("WS",K40), REPT("EF",L40), IF(OR(M40="",M40=0),"",REPT(IF(M40>0,"ZU","ZM"),ABS(M40))), IF(D40="FW","XXFW",IF(D40="BIO","XXBI",IF(D40="ABWWP","XXWP",IF(D40="WP","XXWP",IF(D40="GG","XXGG",""))))) ) -> WSWSWSWSWS | AA40: =CHAR(34)&VLOOKUP(Table1[[#This Row],[Name]],'Massnahmenkarten Texte'!A:C,3,FALSE)&CHAR(34) -> "Hochwertigster Wärmeschutz, luftdichte Gebäudehülle. Die verwendeten Baustoffe sind fossil und verursachen entsprechend höhere graue Energie."
...

Sheet Massnahmenkarten Texte
A1: Name | B1: label_en | C1: Beschreibung | D1: description_en | E1: Voraussetzungen Texte | F1: Quelle | G1: Page | H1: Mehr Infos
A2: Niedertemperatur Radiator | B2: Low-temperature radiator | C2: Niedertemperatur-Radiatoren sind eine günstigere Alternative zu Flächenheizungen und lassen sich im Bestand meist einfacher nachrüsten. Sie ermöglichen niedrigere Vorlauftemperaturen und verbessern damit die Effizienz der Wärmepumpe, bieten aber weniger Komfort und Effizienzpotenzial als Fußboden- oder Deckenheizung. | D2: It's high heating power compared to it's size allows it to work with lower temperature differences, which is very efficient. | E2: Bewege oder platziere den Effizienzmarker EF entsprechend.
A3: Radiatoren mit Lüftern | B3: Radiators with fans | C3: Radiatoren mit Lüftern erhöhen die Wärmeabgabe und können auch bei niedrigeren Vorlauftemperaturen gut funktionieren. Sie sind einfach nachzurüsten, können aber durch Geräusche oder Luftbewegung als störend empfunden werden. | D3: It's high heating power compared to it's size allows it to work with lower temperature differences, which is very efficient. | E3: Bewege oder platziere den Effizienzmarker EF entsprechend.
A4: Fussbodenheizung | B4: Underfloor heating | C4: Eine Fußbodenheizung gibt Wärme über große Flächen ab, ist komfortabel und ermöglicht niedrige Vorlauftemperaturen. Dadurch arbeiten Wärmepumpen effizienter; im Bestand sind aber Bodenaufbau, Bauaufwand und die eher träge Regelung zu beachten. | D4: Surface heating reduces the necessary heating temperature, which increases energy efficiency. An increase in comfort can also be expected. | E4: Bewege oder platziere den Effizienzmarker EF entsprechend. | G4: 35
A5: Deckenheizung | B5: Ceiling heating | C5: Eine Deckenheizung gibt Wärme über große Flächen ab und ermöglicht niedrige Vorlauftemperaturen. Dadurch arbeiten Wärmepumpen effizienter, während Planung, Regelung und Nutzerakzeptanz gut gelöst werden müssen. | D5: Surface heating reduces the necessary heating temperature, which increases energy efficiency. An increase in comfort can also be expected. | E5: Bewege oder platziere den Effizienzmarker EF entsprechend. | G5: 36
A6: Wandheizung | B6: Wall heating | C6: Eine Wandheizung gibt Wärme über große Flächen ab, ist komfortabel und ermöglicht niedrige Vorlauftemperaturen. Dadurch arbeiten Wärmepumpen effizienter; im Bestand sind aber Einbauaufwand, freie Wandflächen und spätere Möblierung zu beachten. | D6: Surface heating reduces the necessary heating temperature, which increases energy efficiency. An increase in comfort can also be expected. | E6: Bewege oder platziere den Effizienzmarker EF entsprechend.
A7: TestMassnahme | B7: Aeä Oeö Ueü ää öö üü szss | C7: Eine Beschreibung hier einfügen, kurz halten oder sie wird abgeschnitten | D7: Some description gös here Keep it short or it will be cut off | E7: Voraussetzung ist 5 WS Wärmeschutz und eine vorhandene Wärmepumpe WP. Falls das dein erstes EF Effizienzsymbol ist, platziere den Effizienzmarker auf das erste Feld der Effizienzleiste.
A8: Fossile Dämmstoffe | B8: Insulation of the top floor ceiling (conventional) | C8: Mineralische oder synthetische Dämmstoffe. Hohe Umweltauswirkungen. | D8: Mineral or synthetic insulation material. While thermal performance is good, the environmental impact is rather big, recycling often not possible and disposal expensive. | F8: https://www.klimaaktiv.at/fileadmin/Bibliothek/Publikationen/2025_Sanierung_Heizungsumstellung.pdf | G8: 12
A9: Holzfaserdämmung | B9: Eco Insulation of top floor ceiling: wood fiber | C9: Natürlicher Dämmstoff. Geringe Umweltbelastung und recyclebar. | D9: Natural insulation materials have a significantly lower impact on the environment than synthetic and mineral ones. | F9: https://www.klimaaktiv.at/fileadmin/Bibliothek/Publikationen/2025_Sanierung_Heizungsumstellung.pdf | G9: 12
A10: Schafwolldämmung | B10: Eco Insulation of the top floor ceiling: sheep's wool | C10: Natürlicher Dämmstoff. Geringe Umweltbelastung und recyclebar. | D10: Natural insulation materials have a significantly lower impact on the environment than synthetic and mineral ones. | F10: https://www.klimaaktiv.at/fileadmin/Bibliothek/Publikationen/2025_Sanierung_Heizungsumstellung.pdf | G10: 12
A11: Zellulosedämmung | B11: Eco Insulation of top floor ceiling: cellulose | C11: Natürlicher Dämmstoff. Geringe Umweltbelastung und recyclebar. | D11: Natural insulation materials have a significantly lower impact on the environment than synthetic and mineral ones. | F11: https://www.klimaaktiv.at/fileadmin/Bibliothek/Publikationen/2025_Sanierung_Heizungsumstellung.pdf | G11: 12
A12: Dachgärten | B12: Roof gardens | C12: Bepflanzte Grünflächen, die auf dem Dach eines Gebäudes angelegt wurden, um ökologische Vorteile und einen höheren Wohnkomfort zu bieten. | D12: Planted green space built on a building’s roof for environmental benefits and amenity.
A13: Thermische Solaranlage | B13: Thermal solar system | C13: Eine thermische Solaranlage nutzt Sonnenwärme für Warmwasser oder Heizungsunterstützung und reduziert so den Heizenergiebedarf. Früher war sie häufiger die Standardlösung am Dach, heute wird oft PV bevorzugt. | D13: Efficient, environmentally simple heating system, mostly used for hot water heating when no PV-system is present. | G13: 30
A14: Kleine Dach-PV-Anlage | B14: Minimal PV system | C14: Eine kleine PV-Anlage ist die einfache Standardlösung und deckt vor allem den direkten Eigenverbrauch. Sie spart Emissionen ohne zusätzlichen Speicher, bleibt aber in ihrem Potenzial begrenzt.
A15: Mittlere Dach-PV-Anlage | B15: Medium-sized PV system | C15: Eine mittlere PV-Anlage ist ein guter Kompromiss zwischen Aufwand, Kosten und Klimawirkung. Sie erzeugt mehr Strom als die kleine Variante und wird mit Speicher oder flexiblen Verbrauchern deutlich wirksamer.
A16: Grosse Dach-PV-Anlage | B16: Large PV system | C16: Eine große PV-Anlage nutzt die verfügbare Dachfläche konsequent und kann viel Emissionen einsparen. Damit der zusätzliche Strom gut genutzt wird, braucht sie meist Speicher oder flexible Verbraucher.
A17: PV-Pergola | B17: PV pergola | C17: Eine PV-Pergola ist eine überdachte Terrasse oder Freifläche, bei der die PV-Module zugleich Schatten spenden und Strom erzeugen. Sie ist aufwendig, erhöht aber die Aufenthaltsqualität und Nutzerzufriedenheit deutlich. | D17: PV-system that provides shade and weather protection for gatherings underneath. Slightly more expensive than conventional panels.
A18: PV Dachziegel | B18: PV roof tiles | C18: Lösung für denkmalgeschützte Dächer mit reduzierter Effizienz im Vergleich zu herkömmlichen Paneelen. | D18: Fashionable solution for roofs with slight efficiency reduction compared to conventional panels.
A19: Standardsanierung | B19: Conventional facade insulation | C19: Das Gebäude wird auf den gesetzlichen Mindestandard gebracht. Der Wärmeschutz verbessert sich, die eingesetzten Materialien sind fossil. | D19: Mineral or synthetic insulation material. While thermal performance is good, the environmental impact is rather big, recycling often not possible and disposal expensive. | F19: https://www.klimaaktiv.at/fileadmin/Bibliothek/Publikationen/2025_Sanierung_Heizungsumstellung.pdf | G19: 11
A20: Ambitionierte Sanierung | B20: Conventional facade insulation | C20: Die Gebäudehülle wird über den Mindeststandard hinaus verbessert. Dadurch sinkt der Heizwärmebedarf stärker, jedoch mit etwas höherem Material- und Investitionsaufwand. | D20: Mineral or synthetic insulation material. While thermal performance is good, the environmental impact is rather big, recycling often not possible and disposal expensive. | F20: https://www.klimaaktiv.at/fileadmin/Bibliothek/Publikationen/2025_Sanierung_Heizungsumstellung.pdf | G20: 11
A21: Passivhaussanierung konventionell | B21: Hemp facade insulation | C21: Hochwertigster Wärmeschutz, luftdichte Gebäudehülle. Die verwendeten Baustoffe sind fossil und verursachen entsprechend höhere graue Energie. | D21: Natural insulation materials have a significantly lower impact on the environment than synthetic and mineral ones. | F21: https://www.klimaaktiv.at/fileadmin/Bibliothek/Publikationen/2025_Sanierung_Heizungsumstellung.pdf | G21: 11 | H21: =F21&"#page="&G21 -> https://www.klimaaktiv.at/fileadmin/Bibliothek/Publikationen/2025_Sanierung_Heizungsumstellung.pdf#page=11
A22: Standardsanierung ökologisch | B22: Conventional facade insulation | C22: Hochwertigster Wärmeschutz, luftdichte Gebäudehülle. Die verwendeten ökologischen Baustoffe reduzieren Emissionen. | D22: Mineral or synthetic insulation material. While thermal performance is good, the environmental impact is rather big, recycling often not possible and disposal expensive. | F22: https://www.klimaaktiv.at/fileadmin/Bibliothek/Publikationen/2025_Sanierung_Heizungsumstellung.pdf | G22: 11
A23: Ambitionierte Sanierung ökologisch | B23: Conventional facade insulation | C23: Die Gebäudehülle wird über den Mindeststandard hinaus mit ökologischen Dämmstoffen verbessert. Dadurch sinkt der Heizwärmebedarf stärker. | D23: Mineral or synthetic insulation material. While thermal performance is good, the environmental impact is rather big, recycling often not possible and disposal expensive. | F23: https://www.klimaaktiv.at/fileadmin/Bibliothek/Publikationen/2025_Sanierung_Heizungsumstellung.pdf | G23: 11
A24: Passivhaussanierung ökologisch | B24: Hemp facade insulation | C24: Natürlicher Dämmstoff. Geringe Umweltbelastung und recyclebar. | D24: Natural insulation materials have a significantly lower impact on the environment than synthetic and mineral ones. | F24: https://www.klimaaktiv.at/fileadmin/Bibliothek/Publikationen/2025_Sanierung_Heizungsumstellung.pdf | G24: 11 | H24: =F24&"#page="&G24 -> https://www.klimaaktiv.at/fileadmin/Bibliothek/Publikationen/2025_Sanierung_Heizungsumstellung.pdf#page=11
A25: Türen abdichten | B25: Sealing doors | C25: Schließen Sie die Spalten zwischen Tür und Türrahmen, um Energieverluste durch Luftströme zu vermeiden. | D25: Close gaps between door and doorframe to prevent energy loss through air streams. | F25: https://ig-lebenszyklus.at/wp-content/uploads/2023/11/Massnahmenkatalog_final.pdf | G25: 20
A26: Türen tauschen | B26: Swap doors | C26: Eine besser isolierte Tür reduziert die Transmissionsverluste. | D26: Install a better insulated door to reduce transmission losses. | F26: https://ig-lebenszyklus.at/wp-content/uploads/2023/11/Massnahmenkatalog_final.pdf | G26: 21
A27: Sanierung Glasfassade | B27: Glass facade renovation | C27: zu speziell | D27: zu speziell | F27: https://ig-lebenszyklus.at/wp-content/uploads/2023/11/Massnahmenkatalog_final.pdf
A28: Dämmputze | B28: Insulating plasters | C28: zu speziell | D28: zu speziell
A29: RENVELOPE | F29: https://renvelope.at/lösung/
A30: Wärmedämmung mit Stuckelementen | B30: Thermal insulation with stucco elements | C30: zu speziell | D30: zu speziell | F30: https://ig-lebenszyklus.at/wp-content/uploads/2023/11/Massnahmenkatalog_final.pdf | G30: 9
A31: Tausch der Verglasung | B31: Box window 2: Replacement of the glazing (the inner sash) | C31: Beim Tausch der Verglasung bleiben die bestehenden Fensterrahmen erhalten, nur die Scheiben werden verbessert. Das ist günstiger und verursacht weniger Eingriff als ein kompletter Fenstertausch, bringt aber nur eine begrenzte Verbesserung des Wärmeschutzes. | D31: Typical renovation measure for pre-WWII residential buildings of vienna. Replacing only the glazing of the window is cheaper than replacing the whole window while still delivering good energy savings. | F31: https://ig-lebenszyklus.at/wp-content/uploads/2023/11/Massnahmenkatalog_final.pdf
A32: Fenstertausch: Plastik | B32: Complete replacement of the box window | C32: Kunststofffenster sind die günstige Standardlösung und verbessern den Wärmeschutz etwas. Sie verursachen geringe bis mittlere graue Emissionen, bleiben aber in Komfort und Klimawirkung begrenzt. | D32: Install a better insulated window to reduce transmission losses.
A33: Fenstertausch: Holz-Alu | B33: Complete replacement of the box window | C33: Holz-Alu-Fenster verbessern den Wärmeschutz, sind aber hochwertiger und langlebiger als Plastikfenster. Sie kosten auch mehr. | D33: Install a better insulated window to reduce transmission losses.
A34: Fenstertausch: Passivhaus | B34: Complete replacement of the box window | C34: Passivhausfenster bieten deutlich besseren Wärmeschutz und erhöhen den Wohnkomfort, besonders durch weniger Zugluft und wärmere Glasoberflächen. Sie sind teurer und verursachen durch die aufwendigere Konstruktion zusätzliche graue Emissionen. | D34: Install a better insulated window to reduce transmission losses.
A35: Fenstertausch: Passivhaus ökologisch | B35: Complete replacement of the box window | C35: Ökologische Passivhausfenster verbinden sehr guten Wärmeschutz mit möglichst klimafreundlichen Materialien. Sie sind die teuerste Variante, reduzieren aber die grauen Emissionen gegenüber konventionellen Passivhausfenstern deutlich. | D35: Install a better insulated window to reduce transmission losses.
A36: Bi-Direktionelles Laden | B36: Bidirectional charging | C36: Ermöglicht die Lastverschiebung über den elektrischen Speicher der E-Auto-Batterie, der Abends wieder teilweise entladen wird. Die Unterstützung der Nutzer ist allerdings nötig. | D36: Enables load shifting through the e-cars battery electric storage.
A37: Flexibles Lastmanagement | C37: Wenn die Nutzer mitspielen, können Verbraucher wie Waschmaschinen oder Geschirrspüler dann einschalten, wenn Erneuerbare zur Verfügung stehen.
A38: Effiziente Haushaltsgeräte | C38: Effizienteste Haushaltsgeräte können den dStromverbrauch deutlich reduzieren
A39: Thermische Flexibilität | C39: Wenn die Nutzer es zulassen, können Wärmepumpen zusätzlichen Strom im Gebäude als Wärme (oder im Sommer durch zusätzliche Kühlung) speichern. So lassen sich noch mehr Erneuerbare einsetzen. | E39: Benötigt Wärmepumpe WP
A40: Kleiner Heimspeicher | B40: Small home storage system | C40: Batteriespeicher werden immer günstiger. Sie können den eigenen PV-Strom in den Abend retten und vermeiden so dreckigeren Netzbezug.
...

Sheet Mapping RealwerteSpielwerte
A1: Wert | B1: Real | C1: Spiel | D1: Skalierung real > spiel | E1: Einheit
A2: Spielrunde | B2: 5 | C2: 1 | D2: =Table3[[#This Row],[Real]]/Table3[[#This Row],[Spiel]] -> 5 | E2: Jahre
A3: Rechnerische Gebäudefläche | B3: 1000 | C3: 1 | D3: =Table3[[#This Row],[Real]]/Table3[[#This Row],[Spiel]] -> 1000 | E3: m²
A4: Siegpunkte/Emissionen | B4: 1 | C4: 1 | D4: =Table3[[#This Row],[Real]]/Table3[[#This Row],[Spiel]] -> 1 | E4: kgCO2/m²BGF
A5: Kosten | B5: 10000 | C5: 1 | D5: =Table3[[#This Row],[Real]]/Table3[[#This Row],[Spiel]] -> 10000 | E5: €
A6: BauEmissionen | B6: 1 | C6: 1 | D6: =Table3[[#This Row],[Real]]/Table3[[#This Row],[Spiel]] -> 1 | E6: kg/CO2/m²BGF
A7: Strombedarf | B7: 5 | C7: 1 | D7: =Table3[[#This Row],[Real]]/Table3[[#This Row],[Spiel]] -> 5 | E7: kWh/m²NGF
A8: Stromproduktion | B8: 5 | C8: 1 | D8: =Table3[[#This Row],[Real]]/Table3[[#This Row],[Spiel]] -> 5 | E8: kWh/m²NGF
A9: Stromspeicher | B9: 5 | C9: 1 | D9: =Table3[[#This Row],[Real]]/Table3[[#This Row],[Spiel]] -> 5 | E9: kWh/m²NGF
A10: Netzbezug | B10: 5 | C10: 1 | D10: =Table3[[#This Row],[Real]]/Table3[[#This Row],[Spiel]] -> 5 | E10: kWh/m²NGF
A11: Wärmeschutz (HWB) | B11: 20 | C11: 1 | D11: =Table3[[#This Row],[Real]]/Table3[[#This Row],[Spiel]] -> 20 | E11: kWh/m²NGF
A12: Wärmepumpen-Effizienz | B12: 1 | C12: 1 | D12: =Table3[[#This Row],[Real]]/Table3[[#This Row],[Spiel]] -> 1
A13: Co2 Intensität Netzbezug Runde 1 | B13: 0.1 | C13: 1 | D13: =Table3[[#This Row],[Real]]/Table3[[#This Row],[Spiel]] -> 0.1 | E13: kgCO2/kWh
A14: Co2 Intensität Netzbezug Runde 2 | B14: 0.05 | C14: 1 | D14: =Table3[[#This Row],[Real]]/Table3[[#This Row],[Spiel]] -> 0.05 | E14: kgCO2/kWh
